2025-08-20 22:35:37,330 INFO: City Sahayak startup [in d:\CitySahayak\app.py:55]
2025-08-20 22:35:48,859 ERROR: Error loading home page: (sqlite3.OperationalError) no such column: notice.priority
[SQL: SELECT notice.id AS notice_id, notice.title AS notice_title, notice.content AS notice_content, notice.priority AS notice_priority, notice.timestamp AS notice_timestamp 
FROM notice ORDER BY CASE WHEN (notice.priority = ?) THEN ? WHEN (notice.priority = ?) THEN ? WHEN (notice.priority = ?) THEN ? ELSE ? END, notice.timestamp DESC
 LIMIT ? OFFSET ?]
[parameters: ('High', 1, 'Normal', 2, 'Low', 3, 4, 10, 0)]
(Background on this error at: https://sqlalche.me/e/20/e3q8) [in d:\CitySahayak\app.py:201]
2025-08-20 22:35:49,180 ERROR: Exception on /favicon.ico [GET] [in C:\Users\LENOVO\AppData\Roaming\Python\Python313\site-packages\flask\app.py:875]
Traceback (most recent call last):
  File "C:\Users\LENOVO\AppData\Roaming\Python\Python313\site-packages\flask\app.py", line 917, in full_dispatch_request
    rv = self.dispatch_request()
  File "C:\Users\LENOVO\AppData\Roaming\Python\Python313\site-packages\flask\app.py", line 891, in dispatch_request
    self.raise_routing_exception(req)
    ~~~~~~~~~~~~~~~~~~~~~~~~~~~~^^^^^
  File "C:\Users\LENOVO\AppData\Roaming\Python\Python313\site-packages\flask\app.py", line 500, in raise_routing_exception
    raise request.routing_exception  # type: ignore[misc]
    ^^^^^^^^^^^^^^^^^^^^^^^^^^^^^^^
  File "C:\Users\LENOVO\AppData\Roaming\Python\Python313\site-packages\flask\ctx.py", line 362, in match_request
    result = self.url_adapter.match(return_rule=True)  # type: ignore
  File "C:\Users\LENOVO\AppData\Roaming\Python\Python313\site-packages\werkzeug\routing\map.py", line 629, in match
    raise NotFound() from None
werkzeug.exceptions.NotFound: 404 Not Found: The requested URL was not found on the server. If you entered the URL manually please check your spelling and try again.

During handling of the above exception, another exception occurred:

Traceback (most recent call last):
  File "C:\Users\LENOVO\AppData\Roaming\Python\Python313\site-packages\flask\app.py", line 1511, in wsgi_app
    response = self.full_dispatch_request()
  File "C:\Users\LENOVO\AppData\Roaming\Python\Python313\site-packages\flask\app.py", line 919, in full_dispatch_request
    rv = self.handle_user_exception(e)
  File "C:\Users\LENOVO\AppData\Roaming\Python\Python313\site-packages\flask\app.py", line 802, in handle_user_exception
    return self.handle_http_exception(e)
           ~~~~~~~~~~~~~~~~~~~~~~~~~~^^^
  File "C:\Users\LENOVO\AppData\Roaming\Python\Python313\site-packages\flask\app.py", line 777, in handle_http_exception
    return self.ensure_sync(handler)(e)  # type: ignore[no-any-return]
           ~~~~~~~~~~~~~~~~~~~~~~~~~^^^
  File "d:\CitySahayak\app.py", line 617, in not_found_error
    return render_template('404.html'), 404
           ~~~~~~~~~~~~~~~^^^^^^^^^^^^
  File "C:\Users\LENOVO\AppData\Roaming\Python\Python313\site-packages\flask\templating.py", line 149, in render_template
    template = app.jinja_env.get_or_select_template(template_name_or_list)
  File "C:\Users\LENOVO\AppData\Roaming\Python\Python313\site-packages\jinja2\environment.py", line 1087, in get_or_select_template
    return self.get_template(template_name_or_list, parent, globals)
           ~~~~~~~~~~~~~~~~~^^^^^^^^^^^^^^^^^^^^^^^^^^^^^^^^^^^^^^^^
  File "C:\Users\LENOVO\AppData\Roaming\Python\Python313\site-packages\jinja2\environment.py", line 1016, in get_template
    return self._load_template(name, globals)
           ~~~~~~~~~~~~~~~~~~~^^^^^^^^^^^^^^^
  File "C:\Users\LENOVO\AppData\Roaming\Python\Python313\site-packages\jinja2\environment.py", line 975, in _load_template
    template = self.loader.load(self, name, self.make_globals(globals))
  File "C:\Users\LENOVO\AppData\Roaming\Python\Python313\site-packages\jinja2\loaders.py", line 126, in load
    source, filename, uptodate = self.get_source(environment, name)
                                 ~~~~~~~~~~~~~~~^^^^^^^^^^^^^^^^^^^
  File "C:\Users\LENOVO\AppData\Roaming\Python\Python313\site-packages\flask\templating.py", line 65, in get_source
    return self._get_source_fast(environment, template)
           ~~~~~~~~~~~~~~~~~~~~~^^^^^^^^^^^^^^^^^^^^^^^
  File "C:\Users\LENOVO\AppData\Roaming\Python\Python313\site-packages\flask\templating.py", line 99, in _get_source_fast
    raise TemplateNotFound(template)
jinja2.exceptions.TemplateNotFound: 404.html
2025-08-20 22:36:04,417 ERROR: Exception on /favicon.ico [GET] [in C:\Users\LENOVO\AppData\Roaming\Python\Python313\site-packages\flask\app.py:875]
Traceback (most recent call last):
  File "C:\Users\LENOVO\AppData\Roaming\Python\Python313\site-packages\flask\app.py", line 917, in full_dispatch_request
    rv = self.dispatch_request()
  File "C:\Users\LENOVO\AppData\Roaming\Python\Python313\site-packages\flask\app.py", line 891, in dispatch_request
    self.raise_routing_exception(req)
    ~~~~~~~~~~~~~~~~~~~~~~~~~~~~^^^^^
  File "C:\Users\LENOVO\AppData\Roaming\Python\Python313\site-packages\flask\app.py", line 500, in raise_routing_exception
    raise request.routing_exception  # type: ignore[misc]
    ^^^^^^^^^^^^^^^^^^^^^^^^^^^^^^^
  File "C:\Users\LENOVO\AppData\Roaming\Python\Python313\site-packages\flask\ctx.py", line 362, in match_request
    result = self.url_adapter.match(return_rule=True)  # type: ignore
  File "C:\Users\LENOVO\AppData\Roaming\Python\Python313\site-packages\werkzeug\routing\map.py", line 629, in match
    raise NotFound() from None
werkzeug.exceptions.NotFound: 404 Not Found: The requested URL was not found on the server. If you entered the URL manually please check your spelling and try again.

During handling of the above exception, another exception occurred:

Traceback (most recent call last):
  File "C:\Users\LENOVO\AppData\Roaming\Python\Python313\site-packages\flask\app.py", line 1511, in wsgi_app
    response = self.full_dispatch_request()
  File "C:\Users\LENOVO\AppData\Roaming\Python\Python313\site-packages\flask\app.py", line 919, in full_dispatch_request
    rv = self.handle_user_exception(e)
  File "C:\Users\LENOVO\AppData\Roaming\Python\Python313\site-packages\flask\app.py", line 802, in handle_user_exception
    return self.handle_http_exception(e)
           ~~~~~~~~~~~~~~~~~~~~~~~~~~^^^
  File "C:\Users\LENOVO\AppData\Roaming\Python\Python313\site-packages\flask\app.py", line 777, in handle_http_exception
    return self.ensure_sync(handler)(e)  # type: ignore[no-any-return]
           ~~~~~~~~~~~~~~~~~~~~~~~~~^^^
  File "d:\CitySahayak\app.py", line 617, in not_found_error
    return render_template('404.html'), 404
           ~~~~~~~~~~~~~~~^^^^^^^^^^^^
  File "C:\Users\LENOVO\AppData\Roaming\Python\Python313\site-packages\flask\templating.py", line 149, in render_template
    template = app.jinja_env.get_or_select_template(template_name_or_list)
  File "C:\Users\LENOVO\AppData\Roaming\Python\Python313\site-packages\jinja2\environment.py", line 1087, in get_or_select_template
    return self.get_template(template_name_or_list, parent, globals)
           ~~~~~~~~~~~~~~~~~^^^^^^^^^^^^^^^^^^^^^^^^^^^^^^^^^^^^^^^^
  File "C:\Users\LENOVO\AppData\Roaming\Python\Python313\site-packages\jinja2\environment.py", line 1016, in get_template
    return self._load_template(name, globals)
           ~~~~~~~~~~~~~~~~~~~^^^^^^^^^^^^^^^
  File "C:\Users\LENOVO\AppData\Roaming\Python\Python313\site-packages\jinja2\environment.py", line 975, in _load_template
    template = self.loader.load(self, name, self.make_globals(globals))
  File "C:\Users\LENOVO\AppData\Roaming\Python\Python313\site-packages\jinja2\loaders.py", line 126, in load
    source, filename, uptodate = self.get_source(environment, name)
                                 ~~~~~~~~~~~~~~~^^^^^^^^^^^^^^^^^^^
  File "C:\Users\LENOVO\AppData\Roaming\Python\Python313\site-packages\flask\templating.py", line 65, in get_source
    return self._get_source_fast(environment, template)
           ~~~~~~~~~~~~~~~~~~~~~^^^^^^^^^^^^^^^^^^^^^^^
  File "C:\Users\LENOVO\AppData\Roaming\Python\Python313\site-packages\flask\templating.py", line 99, in _get_source_fast
    raise TemplateNotFound(template)
jinja2.exceptions.TemplateNotFound: 404.html
2025-08-20 22:36:15,550 ERROR: Login error: 400 Bad Request: The browser (or proxy) sent a request that this server could not understand. [in d:\CitySahayak\app.py:271]
2025-08-20 22:36:15,623 ERROR: Exception on /favicon.ico [GET] [in C:\Users\LENOVO\AppData\Roaming\Python\Python313\site-packages\flask\app.py:875]
Traceback (most recent call last):
  File "C:\Users\LENOVO\AppData\Roaming\Python\Python313\site-packages\flask\app.py", line 917, in full_dispatch_request
    rv = self.dispatch_request()
  File "C:\Users\LENOVO\AppData\Roaming\Python\Python313\site-packages\flask\app.py", line 891, in dispatch_request
    self.raise_routing_exception(req)
    ~~~~~~~~~~~~~~~~~~~~~~~~~~~~^^^^^
  File "C:\Users\LENOVO\AppData\Roaming\Python\Python313\site-packages\flask\app.py", line 500, in raise_routing_exception
    raise request.routing_exception  # type: ignore[misc]
    ^^^^^^^^^^^^^^^^^^^^^^^^^^^^^^^
  File "C:\Users\LENOVO\AppData\Roaming\Python\Python313\site-packages\flask\ctx.py", line 362, in match_request
    result = self.url_adapter.match(return_rule=True)  # type: ignore
  File "C:\Users\LENOVO\AppData\Roaming\Python\Python313\site-packages\werkzeug\routing\map.py", line 629, in match
    raise NotFound() from None
werkzeug.exceptions.NotFound: 404 Not Found: The requested URL was not found on the server. If you entered the URL manually please check your spelling and try again.

During handling of the above exception, another exception occurred:

Traceback (most recent call last):
  File "C:\Users\LENOVO\AppData\Roaming\Python\Python313\site-packages\flask\app.py", line 1511, in wsgi_app
    response = self.full_dispatch_request()
  File "C:\Users\LENOVO\AppData\Roaming\Python\Python313\site-packages\flask\app.py", line 919, in full_dispatch_request
    rv = self.handle_user_exception(e)
  File "C:\Users\LENOVO\AppData\Roaming\Python\Python313\site-packages\flask\app.py", line 802, in handle_user_exception
    return self.handle_http_exception(e)
           ~~~~~~~~~~~~~~~~~~~~~~~~~~^^^
  File "C:\Users\LENOVO\AppData\Roaming\Python\Python313\site-packages\flask\app.py", line 777, in handle_http_exception
    return self.ensure_sync(handler)(e)  # type: ignore[no-any-return]
           ~~~~~~~~~~~~~~~~~~~~~~~~~^^^
  File "d:\CitySahayak\app.py", line 617, in not_found_error
    return render_template('404.html'), 404
           ~~~~~~~~~~~~~~~^^^^^^^^^^^^
  File "C:\Users\LENOVO\AppData\Roaming\Python\Python313\site-packages\flask\templating.py", line 149, in render_template
    template = app.jinja_env.get_or_select_template(template_name_or_list)
  File "C:\Users\LENOVO\AppData\Roaming\Python\Python313\site-packages\jinja2\environment.py", line 1087, in get_or_select_template
    return self.get_template(template_name_or_list, parent, globals)
           ~~~~~~~~~~~~~~~~~^^^^^^^^^^^^^^^^^^^^^^^^^^^^^^^^^^^^^^^^
  File "C:\Users\LENOVO\AppData\Roaming\Python\Python313\site-packages\jinja2\environment.py", line 1016, in get_template
    return self._load_template(name, globals)
           ~~~~~~~~~~~~~~~~~~~^^^^^^^^^^^^^^^
  File "C:\Users\LENOVO\AppData\Roaming\Python\Python313\site-packages\jinja2\environment.py", line 975, in _load_template
    template = self.loader.load(self, name, self.make_globals(globals))
  File "C:\Users\LENOVO\AppData\Roaming\Python\Python313\site-packages\jinja2\loaders.py", line 126, in load
    source, filename, uptodate = self.get_source(environment, name)
                                 ~~~~~~~~~~~~~~~^^^^^^^^^^^^^^^^^^^
  File "C:\Users\LENOVO\AppData\Roaming\Python\Python313\site-packages\flask\templating.py", line 65, in get_source
    return self._get_source_fast(environment, template)
           ~~~~~~~~~~~~~~~~~~~~~^^^^^^^^^^^^^^^^^^^^^^^
  File "C:\Users\LENOVO\AppData\Roaming\Python\Python313\site-packages\flask\templating.py", line 99, in _get_source_fast
    raise TemplateNotFound(template)
jinja2.exceptions.TemplateNotFound: 404.html
2025-08-20 22:36:18,109 ERROR: Exception on /favicon.ico [GET] [in C:\Users\LENOVO\AppData\Roaming\Python\Python313\site-packages\flask\app.py:875]
Traceback (most recent call last):
  File "C:\Users\LENOVO\AppData\Roaming\Python\Python313\site-packages\flask\app.py", line 917, in full_dispatch_request
    rv = self.dispatch_request()
  File "C:\Users\LENOVO\AppData\Roaming\Python\Python313\site-packages\flask\app.py", line 891, in dispatch_request
    self.raise_routing_exception(req)
    ~~~~~~~~~~~~~~~~~~~~~~~~~~~~^^^^^
  File "C:\Users\LENOVO\AppData\Roaming\Python\Python313\site-packages\flask\app.py", line 500, in raise_routing_exception
    raise request.routing_exception  # type: ignore[misc]
    ^^^^^^^^^^^^^^^^^^^^^^^^^^^^^^^
  File "C:\Users\LENOVO\AppData\Roaming\Python\Python313\site-packages\flask\ctx.py", line 362, in match_request
    result = self.url_adapter.match(return_rule=True)  # type: ignore
  File "C:\Users\LENOVO\AppData\Roaming\Python\Python313\site-packages\werkzeug\routing\map.py", line 629, in match
    raise NotFound() from None
werkzeug.exceptions.NotFound: 404 Not Found: The requested URL was not found on the server. If you entered the URL manually please check your spelling and try again.

During handling of the above exception, another exception occurred:

Traceback (most recent call last):
  File "C:\Users\LENOVO\AppData\Roaming\Python\Python313\site-packages\flask\app.py", line 1511, in wsgi_app
    response = self.full_dispatch_request()
  File "C:\Users\LENOVO\AppData\Roaming\Python\Python313\site-packages\flask\app.py", line 919, in full_dispatch_request
    rv = self.handle_user_exception(e)
  File "C:\Users\LENOVO\AppData\Roaming\Python\Python313\site-packages\flask\app.py", line 802, in handle_user_exception
    return self.handle_http_exception(e)
           ~~~~~~~~~~~~~~~~~~~~~~~~~~^^^
  File "C:\Users\LENOVO\AppData\Roaming\Python\Python313\site-packages\flask\app.py", line 777, in handle_http_exception
    return self.ensure_sync(handler)(e)  # type: ignore[no-any-return]
           ~~~~~~~~~~~~~~~~~~~~~~~~~^^^
  File "d:\CitySahayak\app.py", line 617, in not_found_error
    return render_template('404.html'), 404
           ~~~~~~~~~~~~~~~^^^^^^^^^^^^
  File "C:\Users\LENOVO\AppData\Roaming\Python\Python313\site-packages\flask\templating.py", line 149, in render_template
    template = app.jinja_env.get_or_select_template(template_name_or_list)
  File "C:\Users\LENOVO\AppData\Roaming\Python\Python313\site-packages\jinja2\environment.py", line 1087, in get_or_select_template
    return self.get_template(template_name_or_list, parent, globals)
           ~~~~~~~~~~~~~~~~~^^^^^^^^^^^^^^^^^^^^^^^^^^^^^^^^^^^^^^^^
  File "C:\Users\LENOVO\AppData\Roaming\Python\Python313\site-packages\jinja2\environment.py", line 1016, in get_template
    return self._load_template(name, globals)
           ~~~~~~~~~~~~~~~~~~~^^^^^^^^^^^^^^^
  File "C:\Users\LENOVO\AppData\Roaming\Python\Python313\site-packages\jinja2\environment.py", line 975, in _load_template
    template = self.loader.load(self, name, self.make_globals(globals))
  File "C:\Users\LENOVO\AppData\Roaming\Python\Python313\site-packages\jinja2\loaders.py", line 126, in load
    source, filename, uptodate = self.get_source(environment, name)
                                 ~~~~~~~~~~~~~~~^^^^^^^^^^^^^^^^^^^
  File "C:\Users\LENOVO\AppData\Roaming\Python\Python313\site-packages\flask\templating.py", line 65, in get_source
    return self._get_source_fast(environment, template)
           ~~~~~~~~~~~~~~~~~~~~~^^^^^^^^^^^^^^^^^^^^^^^
  File "C:\Users\LENOVO\AppData\Roaming\Python\Python313\site-packages\flask\templating.py", line 99, in _get_source_fast
    raise TemplateNotFound(template)
jinja2.exceptions.TemplateNotFound: 404.html
2025-08-20 22:36:27,162 ERROR: Registration error: (sqlite3.OperationalError) no such column: user.is_admin
[SQL: SELECT user.id AS user_id, user.name AS user_name, user.email AS user_email, user.password AS user_password, user.dob AS user_dob, user.gender AS user_gender, user.address AS user_address, user.state AS user_state, user.pin AS user_pin, user.profile_image AS user_profile_image, user.is_admin AS user_is_admin, user.email_verified AS user_email_verified, user.created_at AS user_created_at 
FROM user 
WHERE user.email = ?
 LIMIT ? OFFSET ?]
[parameters: ('admincitysahayak@gmail.com', 1, 0)]
(Background on this error at: https://sqlalche.me/e/20/e3q8) [in d:\CitySahayak\app.py:245]
2025-08-20 22:36:27,231 ERROR: Exception on /favicon.ico [GET] [in C:\Users\LENOVO\AppData\Roaming\Python\Python313\site-packages\flask\app.py:875]
Traceback (most recent call last):
  File "C:\Users\LENOVO\AppData\Roaming\Python\Python313\site-packages\flask\app.py", line 917, in full_dispatch_request
    rv = self.dispatch_request()
  File "C:\Users\LENOVO\AppData\Roaming\Python\Python313\site-packages\flask\app.py", line 891, in dispatch_request
    self.raise_routing_exception(req)
    ~~~~~~~~~~~~~~~~~~~~~~~~~~~~^^^^^
  File "C:\Users\LENOVO\AppData\Roaming\Python\Python313\site-packages\flask\app.py", line 500, in raise_routing_exception
    raise request.routing_exception  # type: ignore[misc]
    ^^^^^^^^^^^^^^^^^^^^^^^^^^^^^^^
  File "C:\Users\LENOVO\AppData\Roaming\Python\Python313\site-packages\flask\ctx.py", line 362, in match_request
    result = self.url_adapter.match(return_rule=True)  # type: ignore
  File "C:\Users\LENOVO\AppData\Roaming\Python\Python313\site-packages\werkzeug\routing\map.py", line 629, in match
    raise NotFound() from None
werkzeug.exceptions.NotFound: 404 Not Found: The requested URL was not found on the server. If you entered the URL manually please check your spelling and try again.

During handling of the above exception, another exception occurred:

Traceback (most recent call last):
  File "C:\Users\LENOVO\AppData\Roaming\Python\Python313\site-packages\flask\app.py", line 1511, in wsgi_app
    response = self.full_dispatch_request()
  File "C:\Users\LENOVO\AppData\Roaming\Python\Python313\site-packages\flask\app.py", line 919, in full_dispatch_request
    rv = self.handle_user_exception(e)
  File "C:\Users\LENOVO\AppData\Roaming\Python\Python313\site-packages\flask\app.py", line 802, in handle_user_exception
    return self.handle_http_exception(e)
           ~~~~~~~~~~~~~~~~~~~~~~~~~~^^^
  File "C:\Users\LENOVO\AppData\Roaming\Python\Python313\site-packages\flask\app.py", line 777, in handle_http_exception
    return self.ensure_sync(handler)(e)  # type: ignore[no-any-return]
           ~~~~~~~~~~~~~~~~~~~~~~~~~^^^
  File "d:\CitySahayak\app.py", line 617, in not_found_error
    return render_template('404.html'), 404
           ~~~~~~~~~~~~~~~^^^^^^^^^^^^
  File "C:\Users\LENOVO\AppData\Roaming\Python\Python313\site-packages\flask\templating.py", line 149, in render_template
    template = app.jinja_env.get_or_select_template(template_name_or_list)
  File "C:\Users\LENOVO\AppData\Roaming\Python\Python313\site-packages\jinja2\environment.py", line 1087, in get_or_select_template
    return self.get_template(template_name_or_list, parent, globals)
           ~~~~~~~~~~~~~~~~~^^^^^^^^^^^^^^^^^^^^^^^^^^^^^^^^^^^^^^^^
  File "C:\Users\LENOVO\AppData\Roaming\Python\Python313\site-packages\jinja2\environment.py", line 1016, in get_template
    return self._load_template(name, globals)
           ~~~~~~~~~~~~~~~~~~~^^^^^^^^^^^^^^^
  File "C:\Users\LENOVO\AppData\Roaming\Python\Python313\site-packages\jinja2\environment.py", line 975, in _load_template
    template = self.loader.load(self, name, self.make_globals(globals))
  File "C:\Users\LENOVO\AppData\Roaming\Python\Python313\site-packages\jinja2\loaders.py", line 126, in load
    source, filename, uptodate = self.get_source(environment, name)
                                 ~~~~~~~~~~~~~~~^^^^^^^^^^^^^^^^^^^
  File "C:\Users\LENOVO\AppData\Roaming\Python\Python313\site-packages\flask\templating.py", line 65, in get_source
    return self._get_source_fast(environment, template)
           ~~~~~~~~~~~~~~~~~~~~~^^^^^^^^^^^^^^^^^^^^^^^
  File "C:\Users\LENOVO\AppData\Roaming\Python\Python313\site-packages\flask\templating.py", line 99, in _get_source_fast
    raise TemplateNotFound(template)
jinja2.exceptions.TemplateNotFound: 404.html
2025-08-20 22:36:37,814 ERROR: Registration error: (sqlite3.OperationalError) no such column: user.is_admin
[SQL: SELECT user.id AS user_id, user.name AS user_name, user.email AS user_email, user.password AS user_password, user.dob AS user_dob, user.gender AS user_gender, user.address AS user_address, user.state AS user_state, user.pin AS user_pin, user.profile_image AS user_profile_image, user.is_admin AS user_is_admin, user.email_verified AS user_email_verified, user.created_at AS user_created_at 
FROM user 
WHERE user.email = ?
 LIMIT ? OFFSET ?]
[parameters: ('admincitysahayak@gmail.com', 1, 0)]
(Background on this error at: https://sqlalche.me/e/20/e3q8) [in d:\CitySahayak\app.py:245]
2025-08-20 22:36:37,897 ERROR: Exception on /favicon.ico [GET] [in C:\Users\LENOVO\AppData\Roaming\Python\Python313\site-packages\flask\app.py:875]
Traceback (most recent call last):
  File "C:\Users\LENOVO\AppData\Roaming\Python\Python313\site-packages\flask\app.py", line 917, in full_dispatch_request
    rv = self.dispatch_request()
  File "C:\Users\LENOVO\AppData\Roaming\Python\Python313\site-packages\flask\app.py", line 891, in dispatch_request
    self.raise_routing_exception(req)
    ~~~~~~~~~~~~~~~~~~~~~~~~~~~~^^^^^
  File "C:\Users\LENOVO\AppData\Roaming\Python\Python313\site-packages\flask\app.py", line 500, in raise_routing_exception
    raise request.routing_exception  # type: ignore[misc]
    ^^^^^^^^^^^^^^^^^^^^^^^^^^^^^^^
  File "C:\Users\LENOVO\AppData\Roaming\Python\Python313\site-packages\flask\ctx.py", line 362, in match_request
    result = self.url_adapter.match(return_rule=True)  # type: ignore
  File "C:\Users\LENOVO\AppData\Roaming\Python\Python313\site-packages\werkzeug\routing\map.py", line 629, in match
    raise NotFound() from None
werkzeug.exceptions.NotFound: 404 Not Found: The requested URL was not found on the server. If you entered the URL manually please check your spelling and try again.

During handling of the above exception, another exception occurred:

Traceback (most recent call last):
  File "C:\Users\LENOVO\AppData\Roaming\Python\Python313\site-packages\flask\app.py", line 1511, in wsgi_app
    response = self.full_dispatch_request()
  File "C:\Users\LENOVO\AppData\Roaming\Python\Python313\site-packages\flask\app.py", line 919, in full_dispatch_request
    rv = self.handle_user_exception(e)
  File "C:\Users\LENOVO\AppData\Roaming\Python\Python313\site-packages\flask\app.py", line 802, in handle_user_exception
    return self.handle_http_exception(e)
           ~~~~~~~~~~~~~~~~~~~~~~~~~~^^^
  File "C:\Users\LENOVO\AppData\Roaming\Python\Python313\site-packages\flask\app.py", line 777, in handle_http_exception
    return self.ensure_sync(handler)(e)  # type: ignore[no-any-return]
           ~~~~~~~~~~~~~~~~~~~~~~~~~^^^
  File "d:\CitySahayak\app.py", line 617, in not_found_error
    return render_template('404.html'), 404
           ~~~~~~~~~~~~~~~^^^^^^^^^^^^
  File "C:\Users\LENOVO\AppData\Roaming\Python\Python313\site-packages\flask\templating.py", line 149, in render_template
    template = app.jinja_env.get_or_select_template(template_name_or_list)
  File "C:\Users\LENOVO\AppData\Roaming\Python\Python313\site-packages\jinja2\environment.py", line 1087, in get_or_select_template
    return self.get_template(template_name_or_list, parent, globals)
           ~~~~~~~~~~~~~~~~~^^^^^^^^^^^^^^^^^^^^^^^^^^^^^^^^^^^^^^^^
  File "C:\Users\LENOVO\AppData\Roaming\Python\Python313\site-packages\jinja2\environment.py", line 1016, in get_template
    return self._load_template(name, globals)
           ~~~~~~~~~~~~~~~~~~~^^^^^^^^^^^^^^^
  File "C:\Users\LENOVO\AppData\Roaming\Python\Python313\site-packages\jinja2\environment.py", line 975, in _load_template
    template = self.loader.load(self, name, self.make_globals(globals))
  File "C:\Users\LENOVO\AppData\Roaming\Python\Python313\site-packages\jinja2\loaders.py", line 126, in load
    source, filename, uptodate = self.get_source(environment, name)
                                 ~~~~~~~~~~~~~~~^^^^^^^^^^^^^^^^^^^
  File "C:\Users\LENOVO\AppData\Roaming\Python\Python313\site-packages\flask\templating.py", line 65, in get_source
    return self._get_source_fast(environment, template)
           ~~~~~~~~~~~~~~~~~~~~~^^^^^^^^^^^^^^^^^^^^^^^
  File "C:\Users\LENOVO\AppData\Roaming\Python\Python313\site-packages\flask\templating.py", line 99, in _get_source_fast
    raise TemplateNotFound(template)
jinja2.exceptions.TemplateNotFound: 404.html
2025-08-20 22:42:57,328 INFO: City Sahayak startup [in D:\CitySahayak\app.py:55]
2025-08-20 22:44:02,489 INFO: City Sahayak startup [in D:\CitySahayak\app.py:55]
2025-08-20 22:44:13,654 ERROR: Exception on /favicon.ico [GET] [in C:\Users\LENOVO\AppData\Roaming\Python\Python313\site-packages\flask\app.py:875]
Traceback (most recent call last):
  File "C:\Users\LENOVO\AppData\Roaming\Python\Python313\site-packages\flask\app.py", line 917, in full_dispatch_request
    rv = self.dispatch_request()
  File "C:\Users\LENOVO\AppData\Roaming\Python\Python313\site-packages\flask\app.py", line 891, in dispatch_request
    self.raise_routing_exception(req)
    ~~~~~~~~~~~~~~~~~~~~~~~~~~~~^^^^^
  File "C:\Users\LENOVO\AppData\Roaming\Python\Python313\site-packages\flask\app.py", line 500, in raise_routing_exception
    raise request.routing_exception  # type: ignore[misc]
    ^^^^^^^^^^^^^^^^^^^^^^^^^^^^^^^
  File "C:\Users\LENOVO\AppData\Roaming\Python\Python313\site-packages\flask\ctx.py", line 362, in match_request
    result = self.url_adapter.match(return_rule=True)  # type: ignore
  File "C:\Users\LENOVO\AppData\Roaming\Python\Python313\site-packages\werkzeug\routing\map.py", line 629, in match
    raise NotFound() from None
werkzeug.exceptions.NotFound: 404 Not Found: The requested URL was not found on the server. If you entered the URL manually please check your spelling and try again.

During handling of the above exception, another exception occurred:

Traceback (most recent call last):
  File "C:\Users\LENOVO\AppData\Roaming\Python\Python313\site-packages\flask\app.py", line 1511, in wsgi_app
    response = self.full_dispatch_request()
  File "C:\Users\LENOVO\AppData\Roaming\Python\Python313\site-packages\flask\app.py", line 919, in full_dispatch_request
    rv = self.handle_user_exception(e)
  File "C:\Users\LENOVO\AppData\Roaming\Python\Python313\site-packages\flask\app.py", line 802, in handle_user_exception
    return self.handle_http_exception(e)
           ~~~~~~~~~~~~~~~~~~~~~~~~~~^^^
  File "C:\Users\LENOVO\AppData\Roaming\Python\Python313\site-packages\flask\app.py", line 777, in handle_http_exception
    return self.ensure_sync(handler)(e)  # type: ignore[no-any-return]
           ~~~~~~~~~~~~~~~~~~~~~~~~~^^^
  File "D:\CitySahayak\app.py", line 617, in not_found_error
    return render_template('404.html'), 404
           ~~~~~~~~~~~~~~~^^^^^^^^^^^^
  File "C:\Users\LENOVO\AppData\Roaming\Python\Python313\site-packages\flask\templating.py", line 149, in render_template
    template = app.jinja_env.get_or_select_template(template_name_or_list)
  File "C:\Users\LENOVO\AppData\Roaming\Python\Python313\site-packages\jinja2\environment.py", line 1087, in get_or_select_template
    return self.get_template(template_name_or_list, parent, globals)
           ~~~~~~~~~~~~~~~~~^^^^^^^^^^^^^^^^^^^^^^^^^^^^^^^^^^^^^^^^
  File "C:\Users\LENOVO\AppData\Roaming\Python\Python313\site-packages\jinja2\environment.py", line 1016, in get_template
    return self._load_template(name, globals)
           ~~~~~~~~~~~~~~~~~~~^^^^^^^^^^^^^^^
  File "C:\Users\LENOVO\AppData\Roaming\Python\Python313\site-packages\jinja2\environment.py", line 975, in _load_template
    template = self.loader.load(self, name, self.make_globals(globals))
  File "C:\Users\LENOVO\AppData\Roaming\Python\Python313\site-packages\jinja2\loaders.py", line 126, in load
    source, filename, uptodate = self.get_source(environment, name)
                                 ~~~~~~~~~~~~~~~^^^^^^^^^^^^^^^^^^^
  File "C:\Users\LENOVO\AppData\Roaming\Python\Python313\site-packages\flask\templating.py", line 65, in get_source
    return self._get_source_fast(environment, template)
           ~~~~~~~~~~~~~~~~~~~~~^^^^^^^^^^^^^^^^^^^^^^^
  File "C:\Users\LENOVO\AppData\Roaming\Python\Python313\site-packages\flask\templating.py", line 99, in _get_source_fast
    raise TemplateNotFound(template)
jinja2.exceptions.TemplateNotFound: 404.html
2025-08-20 22:44:15,731 ERROR: Exception on /favicon.ico [GET] [in C:\Users\LENOVO\AppData\Roaming\Python\Python313\site-packages\flask\app.py:875]
Traceback (most recent call last):
  File "C:\Users\LENOVO\AppData\Roaming\Python\Python313\site-packages\flask\app.py", line 917, in full_dispatch_request
    rv = self.dispatch_request()
  File "C:\Users\LENOVO\AppData\Roaming\Python\Python313\site-packages\flask\app.py", line 891, in dispatch_request
    self.raise_routing_exception(req)
    ~~~~~~~~~~~~~~~~~~~~~~~~~~~~^^^^^
  File "C:\Users\LENOVO\AppData\Roaming\Python\Python313\site-packages\flask\app.py", line 500, in raise_routing_exception
    raise request.routing_exception  # type: ignore[misc]
    ^^^^^^^^^^^^^^^^^^^^^^^^^^^^^^^
  File "C:\Users\LENOVO\AppData\Roaming\Python\Python313\site-packages\flask\ctx.py", line 362, in match_request
    result = self.url_adapter.match(return_rule=True)  # type: ignore
  File "C:\Users\LENOVO\AppData\Roaming\Python\Python313\site-packages\werkzeug\routing\map.py", line 629, in match
    raise NotFound() from None
werkzeug.exceptions.NotFound: 404 Not Found: The requested URL was not found on the server. If you entered the URL manually please check your spelling and try again.

During handling of the above exception, another exception occurred:

Traceback (most recent call last):
  File "C:\Users\LENOVO\AppData\Roaming\Python\Python313\site-packages\flask\app.py", line 1511, in wsgi_app
    response = self.full_dispatch_request()
  File "C:\Users\LENOVO\AppData\Roaming\Python\Python313\site-packages\flask\app.py", line 919, in full_dispatch_request
    rv = self.handle_user_exception(e)
  File "C:\Users\LENOVO\AppData\Roaming\Python\Python313\site-packages\flask\app.py", line 802, in handle_user_exception
    return self.handle_http_exception(e)
           ~~~~~~~~~~~~~~~~~~~~~~~~~~^^^
  File "C:\Users\LENOVO\AppData\Roaming\Python\Python313\site-packages\flask\app.py", line 777, in handle_http_exception
    return self.ensure_sync(handler)(e)  # type: ignore[no-any-return]
           ~~~~~~~~~~~~~~~~~~~~~~~~~^^^
  File "D:\CitySahayak\app.py", line 617, in not_found_error
    return render_template('404.html'), 404
           ~~~~~~~~~~~~~~~^^^^^^^^^^^^
  File "C:\Users\LENOVO\AppData\Roaming\Python\Python313\site-packages\flask\templating.py", line 149, in render_template
    template = app.jinja_env.get_or_select_template(template_name_or_list)
  File "C:\Users\LENOVO\AppData\Roaming\Python\Python313\site-packages\jinja2\environment.py", line 1087, in get_or_select_template
    return self.get_template(template_name_or_list, parent, globals)
           ~~~~~~~~~~~~~~~~~^^^^^^^^^^^^^^^^^^^^^^^^^^^^^^^^^^^^^^^^
  File "C:\Users\LENOVO\AppData\Roaming\Python\Python313\site-packages\jinja2\environment.py", line 1016, in get_template
    return self._load_template(name, globals)
           ~~~~~~~~~~~~~~~~~~~^^^^^^^^^^^^^^^
  File "C:\Users\LENOVO\AppData\Roaming\Python\Python313\site-packages\jinja2\environment.py", line 975, in _load_template
    template = self.loader.load(self, name, self.make_globals(globals))
  File "C:\Users\LENOVO\AppData\Roaming\Python\Python313\site-packages\jinja2\loaders.py", line 126, in load
    source, filename, uptodate = self.get_source(environment, name)
                                 ~~~~~~~~~~~~~~~^^^^^^^^^^^^^^^^^^^
  File "C:\Users\LENOVO\AppData\Roaming\Python\Python313\site-packages\flask\templating.py", line 65, in get_source
    return self._get_source_fast(environment, template)
           ~~~~~~~~~~~~~~~~~~~~~^^^^^^^^^^^^^^^^^^^^^^^
  File "C:\Users\LENOVO\AppData\Roaming\Python\Python313\site-packages\flask\templating.py", line 99, in _get_source_fast
    raise TemplateNotFound(template)
jinja2.exceptions.TemplateNotFound: 404.html
2025-08-20 22:44:22,650 INFO: New user registered: admincitysahayak@gmail.com [in D:\CitySahayak\app.py:240]
2025-08-20 22:44:22,769 ERROR: Exception on /favicon.ico [GET] [in C:\Users\LENOVO\AppData\Roaming\Python\Python313\site-packages\flask\app.py:875]
Traceback (most recent call last):
  File "C:\Users\LENOVO\AppData\Roaming\Python\Python313\site-packages\flask\app.py", line 917, in full_dispatch_request
    rv = self.dispatch_request()
  File "C:\Users\LENOVO\AppData\Roaming\Python\Python313\site-packages\flask\app.py", line 891, in dispatch_request
    self.raise_routing_exception(req)
    ~~~~~~~~~~~~~~~~~~~~~~~~~~~~^^^^^
  File "C:\Users\LENOVO\AppData\Roaming\Python\Python313\site-packages\flask\app.py", line 500, in raise_routing_exception
    raise request.routing_exception  # type: ignore[misc]
    ^^^^^^^^^^^^^^^^^^^^^^^^^^^^^^^
  File "C:\Users\LENOVO\AppData\Roaming\Python\Python313\site-packages\flask\ctx.py", line 362, in match_request
    result = self.url_adapter.match(return_rule=True)  # type: ignore
  File "C:\Users\LENOVO\AppData\Roaming\Python\Python313\site-packages\werkzeug\routing\map.py", line 629, in match
    raise NotFound() from None
werkzeug.exceptions.NotFound: 404 Not Found: The requested URL was not found on the server. If you entered the URL manually please check your spelling and try again.

During handling of the above exception, another exception occurred:

Traceback (most recent call last):
  File "C:\Users\LENOVO\AppData\Roaming\Python\Python313\site-packages\flask\app.py", line 1511, in wsgi_app
    response = self.full_dispatch_request()
  File "C:\Users\LENOVO\AppData\Roaming\Python\Python313\site-packages\flask\app.py", line 919, in full_dispatch_request
    rv = self.handle_user_exception(e)
  File "C:\Users\LENOVO\AppData\Roaming\Python\Python313\site-packages\flask\app.py", line 802, in handle_user_exception
    return self.handle_http_exception(e)
           ~~~~~~~~~~~~~~~~~~~~~~~~~~^^^
  File "C:\Users\LENOVO\AppData\Roaming\Python\Python313\site-packages\flask\app.py", line 777, in handle_http_exception
    return self.ensure_sync(handler)(e)  # type: ignore[no-any-return]
           ~~~~~~~~~~~~~~~~~~~~~~~~~^^^
  File "D:\CitySahayak\app.py", line 617, in not_found_error
    return render_template('404.html'), 404
           ~~~~~~~~~~~~~~~^^^^^^^^^^^^
  File "C:\Users\LENOVO\AppData\Roaming\Python\Python313\site-packages\flask\templating.py", line 149, in render_template
    template = app.jinja_env.get_or_select_template(template_name_or_list)
  File "C:\Users\LENOVO\AppData\Roaming\Python\Python313\site-packages\jinja2\environment.py", line 1087, in get_or_select_template
    return self.get_template(template_name_or_list, parent, globals)
           ~~~~~~~~~~~~~~~~~^^^^^^^^^^^^^^^^^^^^^^^^^^^^^^^^^^^^^^^^
  File "C:\Users\LENOVO\AppData\Roaming\Python\Python313\site-packages\jinja2\environment.py", line 1016, in get_template
    return self._load_template(name, globals)
           ~~~~~~~~~~~~~~~~~~~^^^^^^^^^^^^^^^
  File "C:\Users\LENOVO\AppData\Roaming\Python\Python313\site-packages\jinja2\environment.py", line 975, in _load_template
    template = self.loader.load(self, name, self.make_globals(globals))
  File "C:\Users\LENOVO\AppData\Roaming\Python\Python313\site-packages\jinja2\loaders.py", line 126, in load
    source, filename, uptodate = self.get_source(environment, name)
                                 ~~~~~~~~~~~~~~~^^^^^^^^^^^^^^^^^^^
  File "C:\Users\LENOVO\AppData\Roaming\Python\Python313\site-packages\flask\templating.py", line 65, in get_source
    return self._get_source_fast(environment, template)
           ~~~~~~~~~~~~~~~~~~~~~^^^^^^^^^^^^^^^^^^^^^^^
  File "C:\Users\LENOVO\AppData\Roaming\Python\Python313\site-packages\flask\templating.py", line 99, in _get_source_fast
    raise TemplateNotFound(template)
jinja2.exceptions.TemplateNotFound: 404.html
2025-08-20 22:44:27,693 ERROR: Login error: 400 Bad Request: The browser (or proxy) sent a request that this server could not understand. [in D:\CitySahayak\app.py:271]
2025-08-20 22:44:27,772 ERROR: Exception on /favicon.ico [GET] [in C:\Users\LENOVO\AppData\Roaming\Python\Python313\site-packages\flask\app.py:875]
Traceback (most recent call last):
  File "C:\Users\LENOVO\AppData\Roaming\Python\Python313\site-packages\flask\app.py", line 917, in full_dispatch_request
    rv = self.dispatch_request()
  File "C:\Users\LENOVO\AppData\Roaming\Python\Python313\site-packages\flask\app.py", line 891, in dispatch_request
    self.raise_routing_exception(req)
    ~~~~~~~~~~~~~~~~~~~~~~~~~~~~^^^^^
  File "C:\Users\LENOVO\AppData\Roaming\Python\Python313\site-packages\flask\app.py", line 500, in raise_routing_exception
    raise request.routing_exception  # type: ignore[misc]
    ^^^^^^^^^^^^^^^^^^^^^^^^^^^^^^^
  File "C:\Users\LENOVO\AppData\Roaming\Python\Python313\site-packages\flask\ctx.py", line 362, in match_request
    result = self.url_adapter.match(return_rule=True)  # type: ignore
  File "C:\Users\LENOVO\AppData\Roaming\Python\Python313\site-packages\werkzeug\routing\map.py", line 629, in match
    raise NotFound() from None
werkzeug.exceptions.NotFound: 404 Not Found: The requested URL was not found on the server. If you entered the URL manually please check your spelling and try again.

During handling of the above exception, another exception occurred:

Traceback (most recent call last):
  File "C:\Users\LENOVO\AppData\Roaming\Python\Python313\site-packages\flask\app.py", line 1511, in wsgi_app
    response = self.full_dispatch_request()
  File "C:\Users\LENOVO\AppData\Roaming\Python\Python313\site-packages\flask\app.py", line 919, in full_dispatch_request
    rv = self.handle_user_exception(e)
  File "C:\Users\LENOVO\AppData\Roaming\Python\Python313\site-packages\flask\app.py", line 802, in handle_user_exception
    return self.handle_http_exception(e)
           ~~~~~~~~~~~~~~~~~~~~~~~~~~^^^
  File "C:\Users\LENOVO\AppData\Roaming\Python\Python313\site-packages\flask\app.py", line 777, in handle_http_exception
    return self.ensure_sync(handler)(e)  # type: ignore[no-any-return]
           ~~~~~~~~~~~~~~~~~~~~~~~~~^^^
  File "D:\CitySahayak\app.py", line 617, in not_found_error
    return render_template('404.html'), 404
           ~~~~~~~~~~~~~~~^^^^^^^^^^^^
  File "C:\Users\LENOVO\AppData\Roaming\Python\Python313\site-packages\flask\templating.py", line 149, in render_template
    template = app.jinja_env.get_or_select_template(template_name_or_list)
  File "C:\Users\LENOVO\AppData\Roaming\Python\Python313\site-packages\jinja2\environment.py", line 1087, in get_or_select_template
    return self.get_template(template_name_or_list, parent, globals)
           ~~~~~~~~~~~~~~~~~^^^^^^^^^^^^^^^^^^^^^^^^^^^^^^^^^^^^^^^^
  File "C:\Users\LENOVO\AppData\Roaming\Python\Python313\site-packages\jinja2\environment.py", line 1016, in get_template
    return self._load_template(name, globals)
           ~~~~~~~~~~~~~~~~~~~^^^^^^^^^^^^^^^
  File "C:\Users\LENOVO\AppData\Roaming\Python\Python313\site-packages\jinja2\environment.py", line 975, in _load_template
    template = self.loader.load(self, name, self.make_globals(globals))
  File "C:\Users\LENOVO\AppData\Roaming\Python\Python313\site-packages\jinja2\loaders.py", line 126, in load
    source, filename, uptodate = self.get_source(environment, name)
                                 ~~~~~~~~~~~~~~~^^^^^^^^^^^^^^^^^^^
  File "C:\Users\LENOVO\AppData\Roaming\Python\Python313\site-packages\flask\templating.py", line 65, in get_source
    return self._get_source_fast(environment, template)
           ~~~~~~~~~~~~~~~~~~~~~^^^^^^^^^^^^^^^^^^^^^^^
  File "C:\Users\LENOVO\AppData\Roaming\Python\Python313\site-packages\flask\templating.py", line 99, in _get_source_fast
    raise TemplateNotFound(template)
jinja2.exceptions.TemplateNotFound: 404.html
2025-08-20 22:44:32,755 ERROR: Login error: 400 Bad Request: The browser (or proxy) sent a request that this server could not understand. [in D:\CitySahayak\app.py:271]
2025-08-20 22:44:32,834 ERROR: Exception on /favicon.ico [GET] [in C:\Users\LENOVO\AppData\Roaming\Python\Python313\site-packages\flask\app.py:875]
Traceback (most recent call last):
  File "C:\Users\LENOVO\AppData\Roaming\Python\Python313\site-packages\flask\app.py", line 917, in full_dispatch_request
    rv = self.dispatch_request()
  File "C:\Users\LENOVO\AppData\Roaming\Python\Python313\site-packages\flask\app.py", line 891, in dispatch_request
    self.raise_routing_exception(req)
    ~~~~~~~~~~~~~~~~~~~~~~~~~~~~^^^^^
  File "C:\Users\LENOVO\AppData\Roaming\Python\Python313\site-packages\flask\app.py", line 500, in raise_routing_exception
    raise request.routing_exception  # type: ignore[misc]
    ^^^^^^^^^^^^^^^^^^^^^^^^^^^^^^^
  File "C:\Users\LENOVO\AppData\Roaming\Python\Python313\site-packages\flask\ctx.py", line 362, in match_request
    result = self.url_adapter.match(return_rule=True)  # type: ignore
  File "C:\Users\LENOVO\AppData\Roaming\Python\Python313\site-packages\werkzeug\routing\map.py", line 629, in match
    raise NotFound() from None
werkzeug.exceptions.NotFound: 404 Not Found: The requested URL was not found on the server. If you entered the URL manually please check your spelling and try again.

During handling of the above exception, another exception occurred:

Traceback (most recent call last):
  File "C:\Users\LENOVO\AppData\Roaming\Python\Python313\site-packages\flask\app.py", line 1511, in wsgi_app
    response = self.full_dispatch_request()
  File "C:\Users\LENOVO\AppData\Roaming\Python\Python313\site-packages\flask\app.py", line 919, in full_dispatch_request
    rv = self.handle_user_exception(e)
  File "C:\Users\LENOVO\AppData\Roaming\Python\Python313\site-packages\flask\app.py", line 802, in handle_user_exception
    return self.handle_http_exception(e)
           ~~~~~~~~~~~~~~~~~~~~~~~~~~^^^
  File "C:\Users\LENOVO\AppData\Roaming\Python\Python313\site-packages\flask\app.py", line 777, in handle_http_exception
    return self.ensure_sync(handler)(e)  # type: ignore[no-any-return]
           ~~~~~~~~~~~~~~~~~~~~~~~~~^^^
  File "D:\CitySahayak\app.py", line 617, in not_found_error
    return render_template('404.html'), 404
           ~~~~~~~~~~~~~~~^^^^^^^^^^^^
  File "C:\Users\LENOVO\AppData\Roaming\Python\Python313\site-packages\flask\templating.py", line 149, in render_template
    template = app.jinja_env.get_or_select_template(template_name_or_list)
  File "C:\Users\LENOVO\AppData\Roaming\Python\Python313\site-packages\jinja2\environment.py", line 1087, in get_or_select_template
    return self.get_template(template_name_or_list, parent, globals)
           ~~~~~~~~~~~~~~~~~^^^^^^^^^^^^^^^^^^^^^^^^^^^^^^^^^^^^^^^^
  File "C:\Users\LENOVO\AppData\Roaming\Python\Python313\site-packages\jinja2\environment.py", line 1016, in get_template
    return self._load_template(name, globals)
           ~~~~~~~~~~~~~~~~~~~^^^^^^^^^^^^^^^
  File "C:\Users\LENOVO\AppData\Roaming\Python\Python313\site-packages\jinja2\environment.py", line 975, in _load_template
    template = self.loader.load(self, name, self.make_globals(globals))
  File "C:\Users\LENOVO\AppData\Roaming\Python\Python313\site-packages\jinja2\loaders.py", line 126, in load
    source, filename, uptodate = self.get_source(environment, name)
                                 ~~~~~~~~~~~~~~~^^^^^^^^^^^^^^^^^^^
  File "C:\Users\LENOVO\AppData\Roaming\Python\Python313\site-packages\flask\templating.py", line 65, in get_source
    return self._get_source_fast(environment, template)
           ~~~~~~~~~~~~~~~~~~~~~^^^^^^^^^^^^^^^^^^^^^^^
  File "C:\Users\LENOVO\AppData\Roaming\Python\Python313\site-packages\flask\templating.py", line 99, in _get_source_fast
    raise TemplateNotFound(template)
jinja2.exceptions.TemplateNotFound: 404.html
2025-08-20 22:44:37,684 ERROR: Login error: 400 Bad Request: The browser (or proxy) sent a request that this server could not understand. [in D:\CitySahayak\app.py:271]
2025-08-20 22:44:37,762 ERROR: Exception on /favicon.ico [GET] [in C:\Users\LENOVO\AppData\Roaming\Python\Python313\site-packages\flask\app.py:875]
Traceback (most recent call last):
  File "C:\Users\LENOVO\AppData\Roaming\Python\Python313\site-packages\flask\app.py", line 917, in full_dispatch_request
    rv = self.dispatch_request()
  File "C:\Users\LENOVO\AppData\Roaming\Python\Python313\site-packages\flask\app.py", line 891, in dispatch_request
    self.raise_routing_exception(req)
    ~~~~~~~~~~~~~~~~~~~~~~~~~~~~^^^^^
  File "C:\Users\LENOVO\AppData\Roaming\Python\Python313\site-packages\flask\app.py", line 500, in raise_routing_exception
    raise request.routing_exception  # type: ignore[misc]
    ^^^^^^^^^^^^^^^^^^^^^^^^^^^^^^^
  File "C:\Users\LENOVO\AppData\Roaming\Python\Python313\site-packages\flask\ctx.py", line 362, in match_request
    result = self.url_adapter.match(return_rule=True)  # type: ignore
  File "C:\Users\LENOVO\AppData\Roaming\Python\Python313\site-packages\werkzeug\routing\map.py", line 629, in match
    raise NotFound() from None
werkzeug.exceptions.NotFound: 404 Not Found: The requested URL was not found on the server. If you entered the URL manually please check your spelling and try again.

During handling of the above exception, another exception occurred:

Traceback (most recent call last):
  File "C:\Users\LENOVO\AppData\Roaming\Python\Python313\site-packages\flask\app.py", line 1511, in wsgi_app
    response = self.full_dispatch_request()
  File "C:\Users\LENOVO\AppData\Roaming\Python\Python313\site-packages\flask\app.py", line 919, in full_dispatch_request
    rv = self.handle_user_exception(e)
  File "C:\Users\LENOVO\AppData\Roaming\Python\Python313\site-packages\flask\app.py", line 802, in handle_user_exception
    return self.handle_http_exception(e)
           ~~~~~~~~~~~~~~~~~~~~~~~~~~^^^
  File "C:\Users\LENOVO\AppData\Roaming\Python\Python313\site-packages\flask\app.py", line 777, in handle_http_exception
    return self.ensure_sync(handler)(e)  # type: ignore[no-any-return]
           ~~~~~~~~~~~~~~~~~~~~~~~~~^^^
  File "D:\CitySahayak\app.py", line 617, in not_found_error
    return render_template('404.html'), 404
           ~~~~~~~~~~~~~~~^^^^^^^^^^^^
  File "C:\Users\LENOVO\AppData\Roaming\Python\Python313\site-packages\flask\templating.py", line 149, in render_template
    template = app.jinja_env.get_or_select_template(template_name_or_list)
  File "C:\Users\LENOVO\AppData\Roaming\Python\Python313\site-packages\jinja2\environment.py", line 1087, in get_or_select_template
    return self.get_template(template_name_or_list, parent, globals)
           ~~~~~~~~~~~~~~~~~^^^^^^^^^^^^^^^^^^^^^^^^^^^^^^^^^^^^^^^^
  File "C:\Users\LENOVO\AppData\Roaming\Python\Python313\site-packages\jinja2\environment.py", line 1016, in get_template
    return self._load_template(name, globals)
           ~~~~~~~~~~~~~~~~~~~^^^^^^^^^^^^^^^
  File "C:\Users\LENOVO\AppData\Roaming\Python\Python313\site-packages\jinja2\environment.py", line 975, in _load_template
    template = self.loader.load(self, name, self.make_globals(globals))
  File "C:\Users\LENOVO\AppData\Roaming\Python\Python313\site-packages\jinja2\loaders.py", line 126, in load
    source, filename, uptodate = self.get_source(environment, name)
                                 ~~~~~~~~~~~~~~~^^^^^^^^^^^^^^^^^^^
  File "C:\Users\LENOVO\AppData\Roaming\Python\Python313\site-packages\flask\templating.py", line 65, in get_source
    return self._get_source_fast(environment, template)
           ~~~~~~~~~~~~~~~~~~~~~^^^^^^^^^^^^^^^^^^^^^^^
  File "C:\Users\LENOVO\AppData\Roaming\Python\Python313\site-packages\flask\templating.py", line 99, in _get_source_fast
    raise TemplateNotFound(template)
jinja2.exceptions.TemplateNotFound: 404.html
2025-08-20 22:44:41,076 ERROR: Exception on /favicon.ico [GET] [in C:\Users\LENOVO\AppData\Roaming\Python\Python313\site-packages\flask\app.py:875]
Traceback (most recent call last):
  File "C:\Users\LENOVO\AppData\Roaming\Python\Python313\site-packages\flask\app.py", line 917, in full_dispatch_request
    rv = self.dispatch_request()
  File "C:\Users\LENOVO\AppData\Roaming\Python\Python313\site-packages\flask\app.py", line 891, in dispatch_request
    self.raise_routing_exception(req)
    ~~~~~~~~~~~~~~~~~~~~~~~~~~~~^^^^^
  File "C:\Users\LENOVO\AppData\Roaming\Python\Python313\site-packages\flask\app.py", line 500, in raise_routing_exception
    raise request.routing_exception  # type: ignore[misc]
    ^^^^^^^^^^^^^^^^^^^^^^^^^^^^^^^
  File "C:\Users\LENOVO\AppData\Roaming\Python\Python313\site-packages\flask\ctx.py", line 362, in match_request
    result = self.url_adapter.match(return_rule=True)  # type: ignore
  File "C:\Users\LENOVO\AppData\Roaming\Python\Python313\site-packages\werkzeug\routing\map.py", line 629, in match
    raise NotFound() from None
werkzeug.exceptions.NotFound: 404 Not Found: The requested URL was not found on the server. If you entered the URL manually please check your spelling and try again.

During handling of the above exception, another exception occurred:

Traceback (most recent call last):
  File "C:\Users\LENOVO\AppData\Roaming\Python\Python313\site-packages\flask\app.py", line 1511, in wsgi_app
    response = self.full_dispatch_request()
  File "C:\Users\LENOVO\AppData\Roaming\Python\Python313\site-packages\flask\app.py", line 919, in full_dispatch_request
    rv = self.handle_user_exception(e)
  File "C:\Users\LENOVO\AppData\Roaming\Python\Python313\site-packages\flask\app.py", line 802, in handle_user_exception
    return self.handle_http_exception(e)
           ~~~~~~~~~~~~~~~~~~~~~~~~~~^^^
  File "C:\Users\LENOVO\AppData\Roaming\Python\Python313\site-packages\flask\app.py", line 777, in handle_http_exception
    return self.ensure_sync(handler)(e)  # type: ignore[no-any-return]
           ~~~~~~~~~~~~~~~~~~~~~~~~~^^^
  File "D:\CitySahayak\app.py", line 617, in not_found_error
    return render_template('404.html'), 404
           ~~~~~~~~~~~~~~~^^^^^^^^^^^^
  File "C:\Users\LENOVO\AppData\Roaming\Python\Python313\site-packages\flask\templating.py", line 149, in render_template
    template = app.jinja_env.get_or_select_template(template_name_or_list)
  File "C:\Users\LENOVO\AppData\Roaming\Python\Python313\site-packages\jinja2\environment.py", line 1087, in get_or_select_template
    return self.get_template(template_name_or_list, parent, globals)
           ~~~~~~~~~~~~~~~~~^^^^^^^^^^^^^^^^^^^^^^^^^^^^^^^^^^^^^^^^
  File "C:\Users\LENOVO\AppData\Roaming\Python\Python313\site-packages\jinja2\environment.py", line 1016, in get_template
    return self._load_template(name, globals)
           ~~~~~~~~~~~~~~~~~~~^^^^^^^^^^^^^^^
  File "C:\Users\LENOVO\AppData\Roaming\Python\Python313\site-packages\jinja2\environment.py", line 975, in _load_template
    template = self.loader.load(self, name, self.make_globals(globals))
  File "C:\Users\LENOVO\AppData\Roaming\Python\Python313\site-packages\jinja2\loaders.py", line 126, in load
    source, filename, uptodate = self.get_source(environment, name)
                                 ~~~~~~~~~~~~~~~^^^^^^^^^^^^^^^^^^^
  File "C:\Users\LENOVO\AppData\Roaming\Python\Python313\site-packages\flask\templating.py", line 65, in get_source
    return self._get_source_fast(environment, template)
           ~~~~~~~~~~~~~~~~~~~~~^^^^^^^^^^^^^^^^^^^^^^^
  File "C:\Users\LENOVO\AppData\Roaming\Python\Python313\site-packages\flask\templating.py", line 99, in _get_source_fast
    raise TemplateNotFound(template)
jinja2.exceptions.TemplateNotFound: 404.html
2025-08-20 22:44:47,939 INFO: New user registered: bishal9692@gmail.com [in D:\CitySahayak\app.py:240]
2025-08-20 22:44:48,045 ERROR: Exception on /favicon.ico [GET] [in C:\Users\LENOVO\AppData\Roaming\Python\Python313\site-packages\flask\app.py:875]
Traceback (most recent call last):
  File "C:\Users\LENOVO\AppData\Roaming\Python\Python313\site-packages\flask\app.py", line 917, in full_dispatch_request
    rv = self.dispatch_request()
  File "C:\Users\LENOVO\AppData\Roaming\Python\Python313\site-packages\flask\app.py", line 891, in dispatch_request
    self.raise_routing_exception(req)
    ~~~~~~~~~~~~~~~~~~~~~~~~~~~~^^^^^
  File "C:\Users\LENOVO\AppData\Roaming\Python\Python313\site-packages\flask\app.py", line 500, in raise_routing_exception
    raise request.routing_exception  # type: ignore[misc]
    ^^^^^^^^^^^^^^^^^^^^^^^^^^^^^^^
  File "C:\Users\LENOVO\AppData\Roaming\Python\Python313\site-packages\flask\ctx.py", line 362, in match_request
    result = self.url_adapter.match(return_rule=True)  # type: ignore
  File "C:\Users\LENOVO\AppData\Roaming\Python\Python313\site-packages\werkzeug\routing\map.py", line 629, in match
    raise NotFound() from None
werkzeug.exceptions.NotFound: 404 Not Found: The requested URL was not found on the server. If you entered the URL manually please check your spelling and try again.

During handling of the above exception, another exception occurred:

Traceback (most recent call last):
  File "C:\Users\LENOVO\AppData\Roaming\Python\Python313\site-packages\flask\app.py", line 1511, in wsgi_app
    response = self.full_dispatch_request()
  File "C:\Users\LENOVO\AppData\Roaming\Python\Python313\site-packages\flask\app.py", line 919, in full_dispatch_request
    rv = self.handle_user_exception(e)
  File "C:\Users\LENOVO\AppData\Roaming\Python\Python313\site-packages\flask\app.py", line 802, in handle_user_exception
    return self.handle_http_exception(e)
           ~~~~~~~~~~~~~~~~~~~~~~~~~~^^^
  File "C:\Users\LENOVO\AppData\Roaming\Python\Python313\site-packages\flask\app.py", line 777, in handle_http_exception
    return self.ensure_sync(handler)(e)  # type: ignore[no-any-return]
           ~~~~~~~~~~~~~~~~~~~~~~~~~^^^
  File "D:\CitySahayak\app.py", line 617, in not_found_error
    return render_template('404.html'), 404
           ~~~~~~~~~~~~~~~^^^^^^^^^^^^
  File "C:\Users\LENOVO\AppData\Roaming\Python\Python313\site-packages\flask\templating.py", line 149, in render_template
    template = app.jinja_env.get_or_select_template(template_name_or_list)
  File "C:\Users\LENOVO\AppData\Roaming\Python\Python313\site-packages\jinja2\environment.py", line 1087, in get_or_select_template
    return self.get_template(template_name_or_list, parent, globals)
           ~~~~~~~~~~~~~~~~~^^^^^^^^^^^^^^^^^^^^^^^^^^^^^^^^^^^^^^^^
  File "C:\Users\LENOVO\AppData\Roaming\Python\Python313\site-packages\jinja2\environment.py", line 1016, in get_template
    return self._load_template(name, globals)
           ~~~~~~~~~~~~~~~~~~~^^^^^^^^^^^^^^^
  File "C:\Users\LENOVO\AppData\Roaming\Python\Python313\site-packages\jinja2\environment.py", line 975, in _load_template
    template = self.loader.load(self, name, self.make_globals(globals))
  File "C:\Users\LENOVO\AppData\Roaming\Python\Python313\site-packages\jinja2\loaders.py", line 126, in load
    source, filename, uptodate = self.get_source(environment, name)
                                 ~~~~~~~~~~~~~~~^^^^^^^^^^^^^^^^^^^
  File "C:\Users\LENOVO\AppData\Roaming\Python\Python313\site-packages\flask\templating.py", line 65, in get_source
    return self._get_source_fast(environment, template)
           ~~~~~~~~~~~~~~~~~~~~~^^^^^^^^^^^^^^^^^^^^^^^
  File "C:\Users\LENOVO\AppData\Roaming\Python\Python313\site-packages\flask\templating.py", line 99, in _get_source_fast
    raise TemplateNotFound(template)
jinja2.exceptions.TemplateNotFound: 404.html
2025-08-20 22:44:52,151 ERROR: Exception on /favicon.ico [GET] [in C:\Users\LENOVO\AppData\Roaming\Python\Python313\site-packages\flask\app.py:875]
Traceback (most recent call last):
  File "C:\Users\LENOVO\AppData\Roaming\Python\Python313\site-packages\flask\app.py", line 917, in full_dispatch_request
    rv = self.dispatch_request()
  File "C:\Users\LENOVO\AppData\Roaming\Python\Python313\site-packages\flask\app.py", line 891, in dispatch_request
    self.raise_routing_exception(req)
    ~~~~~~~~~~~~~~~~~~~~~~~~~~~~^^^^^
  File "C:\Users\LENOVO\AppData\Roaming\Python\Python313\site-packages\flask\app.py", line 500, in raise_routing_exception
    raise request.routing_exception  # type: ignore[misc]
    ^^^^^^^^^^^^^^^^^^^^^^^^^^^^^^^
  File "C:\Users\LENOVO\AppData\Roaming\Python\Python313\site-packages\flask\ctx.py", line 362, in match_request
    result = self.url_adapter.match(return_rule=True)  # type: ignore
  File "C:\Users\LENOVO\AppData\Roaming\Python\Python313\site-packages\werkzeug\routing\map.py", line 629, in match
    raise NotFound() from None
werkzeug.exceptions.NotFound: 404 Not Found: The requested URL was not found on the server. If you entered the URL manually please check your spelling and try again.

During handling of the above exception, another exception occurred:

Traceback (most recent call last):
  File "C:\Users\LENOVO\AppData\Roaming\Python\Python313\site-packages\flask\app.py", line 1511, in wsgi_app
    response = self.full_dispatch_request()
  File "C:\Users\LENOVO\AppData\Roaming\Python\Python313\site-packages\flask\app.py", line 919, in full_dispatch_request
    rv = self.handle_user_exception(e)
  File "C:\Users\LENOVO\AppData\Roaming\Python\Python313\site-packages\flask\app.py", line 802, in handle_user_exception
    return self.handle_http_exception(e)
           ~~~~~~~~~~~~~~~~~~~~~~~~~~^^^
  File "C:\Users\LENOVO\AppData\Roaming\Python\Python313\site-packages\flask\app.py", line 777, in handle_http_exception
    return self.ensure_sync(handler)(e)  # type: ignore[no-any-return]
           ~~~~~~~~~~~~~~~~~~~~~~~~~^^^
  File "D:\CitySahayak\app.py", line 617, in not_found_error
    return render_template('404.html'), 404
           ~~~~~~~~~~~~~~~^^^^^^^^^^^^
  File "C:\Users\LENOVO\AppData\Roaming\Python\Python313\site-packages\flask\templating.py", line 149, in render_template
    template = app.jinja_env.get_or_select_template(template_name_or_list)
  File "C:\Users\LENOVO\AppData\Roaming\Python\Python313\site-packages\jinja2\environment.py", line 1087, in get_or_select_template
    return self.get_template(template_name_or_list, parent, globals)
           ~~~~~~~~~~~~~~~~~^^^^^^^^^^^^^^^^^^^^^^^^^^^^^^^^^^^^^^^^
  File "C:\Users\LENOVO\AppData\Roaming\Python\Python313\site-packages\jinja2\environment.py", line 1016, in get_template
    return self._load_template(name, globals)
           ~~~~~~~~~~~~~~~~~~~^^^^^^^^^^^^^^^
  File "C:\Users\LENOVO\AppData\Roaming\Python\Python313\site-packages\jinja2\environment.py", line 975, in _load_template
    template = self.loader.load(self, name, self.make_globals(globals))
  File "C:\Users\LENOVO\AppData\Roaming\Python\Python313\site-packages\jinja2\loaders.py", line 126, in load
    source, filename, uptodate = self.get_source(environment, name)
                                 ~~~~~~~~~~~~~~~^^^^^^^^^^^^^^^^^^^
  File "C:\Users\LENOVO\AppData\Roaming\Python\Python313\site-packages\flask\templating.py", line 65, in get_source
    return self._get_source_fast(environment, template)
           ~~~~~~~~~~~~~~~~~~~~~^^^^^^^^^^^^^^^^^^^^^^^
  File "C:\Users\LENOVO\AppData\Roaming\Python\Python313\site-packages\flask\templating.py", line 99, in _get_source_fast
    raise TemplateNotFound(template)
jinja2.exceptions.TemplateNotFound: 404.html
2025-08-20 22:44:57,867 ERROR: Exception on /favicon.ico [GET] [in C:\Users\LENOVO\AppData\Roaming\Python\Python313\site-packages\flask\app.py:875]
Traceback (most recent call last):
  File "C:\Users\LENOVO\AppData\Roaming\Python\Python313\site-packages\flask\app.py", line 917, in full_dispatch_request
    rv = self.dispatch_request()
  File "C:\Users\LENOVO\AppData\Roaming\Python\Python313\site-packages\flask\app.py", line 891, in dispatch_request
    self.raise_routing_exception(req)
    ~~~~~~~~~~~~~~~~~~~~~~~~~~~~^^^^^
  File "C:\Users\LENOVO\AppData\Roaming\Python\Python313\site-packages\flask\app.py", line 500, in raise_routing_exception
    raise request.routing_exception  # type: ignore[misc]
    ^^^^^^^^^^^^^^^^^^^^^^^^^^^^^^^
  File "C:\Users\LENOVO\AppData\Roaming\Python\Python313\site-packages\flask\ctx.py", line 362, in match_request
    result = self.url_adapter.match(return_rule=True)  # type: ignore
  File "C:\Users\LENOVO\AppData\Roaming\Python\Python313\site-packages\werkzeug\routing\map.py", line 629, in match
    raise NotFound() from None
werkzeug.exceptions.NotFound: 404 Not Found: The requested URL was not found on the server. If you entered the URL manually please check your spelling and try again.

During handling of the above exception, another exception occurred:

Traceback (most recent call last):
  File "C:\Users\LENOVO\AppData\Roaming\Python\Python313\site-packages\flask\app.py", line 1511, in wsgi_app
    response = self.full_dispatch_request()
  File "C:\Users\LENOVO\AppData\Roaming\Python\Python313\site-packages\flask\app.py", line 919, in full_dispatch_request
    rv = self.handle_user_exception(e)
  File "C:\Users\LENOVO\AppData\Roaming\Python\Python313\site-packages\flask\app.py", line 802, in handle_user_exception
    return self.handle_http_exception(e)
           ~~~~~~~~~~~~~~~~~~~~~~~~~~^^^
  File "C:\Users\LENOVO\AppData\Roaming\Python\Python313\site-packages\flask\app.py", line 777, in handle_http_exception
    return self.ensure_sync(handler)(e)  # type: ignore[no-any-return]
           ~~~~~~~~~~~~~~~~~~~~~~~~~^^^
  File "D:\CitySahayak\app.py", line 617, in not_found_error
    return render_template('404.html'), 404
           ~~~~~~~~~~~~~~~^^^^^^^^^^^^
  File "C:\Users\LENOVO\AppData\Roaming\Python\Python313\site-packages\flask\templating.py", line 149, in render_template
    template = app.jinja_env.get_or_select_template(template_name_or_list)
  File "C:\Users\LENOVO\AppData\Roaming\Python\Python313\site-packages\jinja2\environment.py", line 1087, in get_or_select_template
    return self.get_template(template_name_or_list, parent, globals)
           ~~~~~~~~~~~~~~~~~^^^^^^^^^^^^^^^^^^^^^^^^^^^^^^^^^^^^^^^^
  File "C:\Users\LENOVO\AppData\Roaming\Python\Python313\site-packages\jinja2\environment.py", line 1016, in get_template
    return self._load_template(name, globals)
           ~~~~~~~~~~~~~~~~~~~^^^^^^^^^^^^^^^
  File "C:\Users\LENOVO\AppData\Roaming\Python\Python313\site-packages\jinja2\environment.py", line 975, in _load_template
    template = self.loader.load(self, name, self.make_globals(globals))
  File "C:\Users\LENOVO\AppData\Roaming\Python\Python313\site-packages\jinja2\loaders.py", line 126, in load
    source, filename, uptodate = self.get_source(environment, name)
                                 ~~~~~~~~~~~~~~~^^^^^^^^^^^^^^^^^^^
  File "C:\Users\LENOVO\AppData\Roaming\Python\Python313\site-packages\flask\templating.py", line 65, in get_source
    return self._get_source_fast(environment, template)
           ~~~~~~~~~~~~~~~~~~~~~^^^^^^^^^^^^^^^^^^^^^^^
  File "C:\Users\LENOVO\AppData\Roaming\Python\Python313\site-packages\flask\templating.py", line 99, in _get_source_fast
    raise TemplateNotFound(template)
jinja2.exceptions.TemplateNotFound: 404.html
2025-08-20 22:45:02,305 ERROR: Exception on /favicon.ico [GET] [in C:\Users\LENOVO\AppData\Roaming\Python\Python313\site-packages\flask\app.py:875]
Traceback (most recent call last):
  File "C:\Users\LENOVO\AppData\Roaming\Python\Python313\site-packages\flask\app.py", line 917, in full_dispatch_request
    rv = self.dispatch_request()
  File "C:\Users\LENOVO\AppData\Roaming\Python\Python313\site-packages\flask\app.py", line 891, in dispatch_request
    self.raise_routing_exception(req)
    ~~~~~~~~~~~~~~~~~~~~~~~~~~~~^^^^^
  File "C:\Users\LENOVO\AppData\Roaming\Python\Python313\site-packages\flask\app.py", line 500, in raise_routing_exception
    raise request.routing_exception  # type: ignore[misc]
    ^^^^^^^^^^^^^^^^^^^^^^^^^^^^^^^
  File "C:\Users\LENOVO\AppData\Roaming\Python\Python313\site-packages\flask\ctx.py", line 362, in match_request
    result = self.url_adapter.match(return_rule=True)  # type: ignore
  File "C:\Users\LENOVO\AppData\Roaming\Python\Python313\site-packages\werkzeug\routing\map.py", line 629, in match
    raise NotFound() from None
werkzeug.exceptions.NotFound: 404 Not Found: The requested URL was not found on the server. If you entered the URL manually please check your spelling and try again.

During handling of the above exception, another exception occurred:

Traceback (most recent call last):
  File "C:\Users\LENOVO\AppData\Roaming\Python\Python313\site-packages\flask\app.py", line 1511, in wsgi_app
    response = self.full_dispatch_request()
  File "C:\Users\LENOVO\AppData\Roaming\Python\Python313\site-packages\flask\app.py", line 919, in full_dispatch_request
    rv = self.handle_user_exception(e)
  File "C:\Users\LENOVO\AppData\Roaming\Python\Python313\site-packages\flask\app.py", line 802, in handle_user_exception
    return self.handle_http_exception(e)
           ~~~~~~~~~~~~~~~~~~~~~~~~~~^^^
  File "C:\Users\LENOVO\AppData\Roaming\Python\Python313\site-packages\flask\app.py", line 777, in handle_http_exception
    return self.ensure_sync(handler)(e)  # type: ignore[no-any-return]
           ~~~~~~~~~~~~~~~~~~~~~~~~~^^^
  File "D:\CitySahayak\app.py", line 617, in not_found_error
    return render_template('404.html'), 404
           ~~~~~~~~~~~~~~~^^^^^^^^^^^^
  File "C:\Users\LENOVO\AppData\Roaming\Python\Python313\site-packages\flask\templating.py", line 149, in render_template
    template = app.jinja_env.get_or_select_template(template_name_or_list)
  File "C:\Users\LENOVO\AppData\Roaming\Python\Python313\site-packages\jinja2\environment.py", line 1087, in get_or_select_template
    return self.get_template(template_name_or_list, parent, globals)
           ~~~~~~~~~~~~~~~~~^^^^^^^^^^^^^^^^^^^^^^^^^^^^^^^^^^^^^^^^
  File "C:\Users\LENOVO\AppData\Roaming\Python\Python313\site-packages\jinja2\environment.py", line 1016, in get_template
    return self._load_template(name, globals)
           ~~~~~~~~~~~~~~~~~~~^^^^^^^^^^^^^^^
  File "C:\Users\LENOVO\AppData\Roaming\Python\Python313\site-packages\jinja2\environment.py", line 975, in _load_template
    template = self.loader.load(self, name, self.make_globals(globals))
  File "C:\Users\LENOVO\AppData\Roaming\Python\Python313\site-packages\jinja2\loaders.py", line 126, in load
    source, filename, uptodate = self.get_source(environment, name)
                                 ~~~~~~~~~~~~~~~^^^^^^^^^^^^^^^^^^^
  File "C:\Users\LENOVO\AppData\Roaming\Python\Python313\site-packages\flask\templating.py", line 65, in get_source
    return self._get_source_fast(environment, template)
           ~~~~~~~~~~~~~~~~~~~~~^^^^^^^^^^^^^^^^^^^^^^^
  File "C:\Users\LENOVO\AppData\Roaming\Python\Python313\site-packages\flask\templating.py", line 99, in _get_source_fast
    raise TemplateNotFound(template)
jinja2.exceptions.TemplateNotFound: 404.html
2025-08-20 22:51:15,929 INFO: City Sahayak startup [in D:\CitySahayak\app.py:55]
2025-08-20 22:51:47,853 INFO: City Sahayak startup [in D:\CitySahayak\app.py:55]
2025-08-20 22:52:16,710 INFO: New user registered: bishal9692@gmail.com [in D:\CitySahayak\app.py:232]
